<sdf version='1.7'>
  <model name='matrice_600'>
    <link name='base_link'>
      <inertial>
        <pose>-0.003207 0.001698 -0.022184 0 -0 0</pose>
        <mass>1.07072</mass>
        <inertia>
          <ixx>0.00252591</ixx>
          <ixy>-1.82102e-07</ixy>
          <ixz>-1.47309e-07</ixz>
          <iyy>0.00275874</iyy>
          <iyz>4.17698e-08</iyz>
          <izz>0.00498886</izz>
        </inertia>
      </inertial>
      <collision name='base_link_collision'>
        <pose>0 0 0 0 -0 0</pose>
        <geometry>
          <mesh>
            <scale>1 1 1</scale>
            <uri>model://matrice_600/meshes/base_link.STL</uri>
          </mesh>
        </geometry>
      </collision>
      <visual name='base_link_visual'>
        <pose>0 0 0 0 -0 0</pose>
        <geometry>
          <mesh>
            <scale>1 1 1</scale>
            <uri>model://matrice_600/meshes/base_link.STL</uri>
          </mesh>
        </geometry>
      </visual>
    </link>

    <link name='/imu_link'>
      <pose>0 0 0.02 0 0 0</pose>
      <inertial>
        <pose>0 0 0 0 0 0</pose>
        <mass>0.015</mass>
        <inertia>
          <ixx>1e-05</ixx>
          <ixy>0</ixy>
          <ixz>0</ixz>
          <iyy>1e-05</iyy>
          <iyz>0</iyz>
          <izz>1e-05</izz>
        </inertia>
      </inertial>
    </link>
    <joint name='/imu_joint' type='revolute'>
      <child>/imu_link</child>
      <parent>base_link</parent>
      <axis>
        <xyz>1 0 0</xyz>
        <limit>
          <lower>0</lower>
          <upper>0</upper>
          <effort>0</effort>
          <velocity>0</velocity>
        </limit>
        <dynamics>
          <spring_reference>0</spring_reference>
          <spring_stiffness>0</spring_stiffness>
        </dynamics>
        <use_parent_model_frame>1</use_parent_model_frame>
      </axis>
    </joint>
    
    
    <joint name='LG_left_joint' type='revolute'>
      <pose relative_to='base_link'>0.019409 0.098608 -0.1042 1.5708 -0.045048 1.5708</pose>
      <parent>base_link</parent>
      <child>LG_left_link</child>
      <axis>
        <xyz>0 0 1</xyz>
        <limit>
          <lower>0</lower>
          <upper>0.1</upper>
          <effort>300</effort>
          <velocity>1</velocity>
        </limit>
        <dynamics>
          <damping>0.1</damping>
          <friction>0.1</friction>
          <spring_reference>0</spring_reference>
          <spring_stiffness>0</spring_stiffness>
        </dynamics>
      </axis>
    </joint>
    <link name='LG_left_link'>
      <pose relative_to='LG_left_joint'>0 0 0 0 -0 0</pose>
      <inertial>
        <pose>0.12212 -0.33864 -0.017257 0 -0 0</pose>
        <mass>0.121</mass>
        <inertia>
          <ixx>0.0011624</ixx>
          <ixy>0.00014898</ixy>
          <ixz>7.8865e-07</ixz>
          <iyy>0.00081775</iyy>
          <iyz>1.5264e-07</iyz>
          <izz>0.00049006</izz>
        </inertia>
      </inertial>
      <collision name='LG_left_link_collision'>
        <pose>0 0 0 0 -0 0</pose>
        <geometry>
          <mesh>
            <scale>1 1 1</scale>
            <uri>model://matrice_600/meshes/LG_left_link.STL</uri>
          </mesh>
        </geometry>
      </collision>
      <visual name='LG_left_link_visual'>
        <pose>0 0 0 0 -0 0</pose>
        <geometry>
          <mesh>
            <scale>1 1 1</scale>
            <uri>model://matrice_600/meshes/LG_left_link.STL</uri>
          </mesh>
        </geometry>
      </visual>
    </link>
    <joint name='Lg_right_joint' type='revolute'>
      <pose relative_to='base_link'>0.019409 -0.098708 -0.1042 1.5708 -0.045048 -1.5708</pose>
      <parent>base_link</parent>
      <child>LG_right_link</child>
      <axis>
        <xyz>0 0 1</xyz>
        <limit>
          <lower>0</lower>
          <upper>0.1</upper>
          <effort>300</effort>
          <velocity>1</velocity>
        </limit>
        <dynamics>
          <damping>0.1</damping>
          <friction>0.1</friction>
          <spring_reference>0</spring_reference>
          <spring_stiffness>0</spring_stiffness>
        </dynamics>
      </axis>
    </joint>
    <link name='LG_right_link'>
      <pose relative_to='Lg_right_joint'>0 0 0 0 -0 0</pose>
      <inertial>
        <pose>0.12212 -0.33864 0.020743 0 -0 0</pose>
        <mass>0.121</mass>
        <inertia>
          <ixx>0.0011624</ixx>
          <ixy>0.00014898</ixy>
          <ixz>7.8865e-07</ixz>
          <iyy>0.00081775</iyy>
          <iyz>1.5264e-07</iyz>
          <izz>0.00049006</izz>
        </inertia>
      </inertial>
      <collision name='LG_right_link_collision'>
        <pose>0 0 0 0 -0 0</pose>
        <geometry>
          <mesh>
            <scale>1 1 1</scale>
            <uri>model://matrice_600/meshes/LG_right_link.STL</uri>
          </mesh>
        </geometry>
      </collision>
      <visual name='LG_right_link_visual'>
        <pose>0 0 0 0 -0 0</pose>
        <geometry>
          <mesh>
            <scale>1 1 1</scale>
            <uri>model://matrice_600/meshes/LG_right_link.STL</uri>
          </mesh>
        </geometry>
      </visual>
    </link>
    <joint name='Motor3_joint' type='revolute'>
      <pose relative_to='base_link'>0.50036 0.2886 0.012238 -3.0753 0.11027 -2.1217</pose>
      <parent>base_link</parent>
      <child>Motor3_link</child>
      <axis>
        <xyz>0 0 1</xyz>
        <limit>
          <lower>-1e+16</lower>
          <upper>1e+16</upper>
        </limit>
        <dynamics>
          
          <spring_reference>0</spring_reference>
          <spring_stiffness>0</spring_stiffness>
        </dynamics>
      </axis>
    </joint>
    <link name='Motor3_link'>
      <pose relative_to='Motor3_joint'>0 0 0 0 -0 0</pose>
      <inertial>
        <pose>0.006488 0.007682 -0.070942 0 -0 0</pose>
        <mass>0.11399</mass>
        <inertia>
          <ixx>0.00019871</ixx>
          <ixy>0.00025974</ixy>
          <ixz>-4.6197e-06</ixz>
          <iyy>0.00036739</iyy>
          <iyz>3.2887e-06</iyz>
          <izz>0.00056352</izz>
        </inertia>
      </inertial>
      <collision name='Motor3_collision'>
        <pose>0 0 0 0 -0 0</pose>
        <geometry>
          <mesh>
            <scale>1 1 1</scale>
            <uri>model://matrice_600/meshes/Motor1_front_left_link.STL</uri>
          </mesh>
        </geometry>
      </collision>
      <visual name='Motor3_visual'>
        <pose>0 0 0 0 -0 0</pose>
        <geometry>
          <mesh>
            <scale>1 1 1</scale>
            <uri>model://matrice_600/meshes/Motor1_front_left_link.STL</uri>
          </mesh>
        </geometry>
      </visual>
    </link>
    <joint name='Motor5_joint' type='revolute'>
      <pose relative_to='base_link'>0.50048 -0.28877 0.011225 0.13742 0.012088 -2.2723</pose>
      <parent>base_link</parent>
      <child>Motor5_link</child>
      <axis>
        <xyz>0 0 1</xyz>
        <limit>
          
          <lower>-1e+16</lower>
          <upper>1e+16</upper>
        </limit>
        <dynamics>
          
          <spring_reference>0</spring_reference>
          <spring_stiffness>0</spring_stiffness>
        </dynamics>
      </axis>
    </joint>
    <link name='Motor5_link'>
      <pose relative_to='Motor5_joint'>0 0 0 0 -0 0</pose>
      <inertial>
        <pose>0.000906 -4e-06 0.072036 0 -0 0</pose>
        <mass>0.056995</mass>
        <inertia>
          <ixx>8.9919e-05</ixx>
          <ixy>-0.00012681</ixy>
          <ixz>2.4293e-06</ixz>
          <iyy>0.00019314</iyy>
          <iyz>1.6056e-06</iyz>
          <izz>0.00028176</izz>
        </inertia>
      </inertial>
      <collision name='Motor5_collision'>
        <pose>0 0 0 0 -0 0</pose>
        <geometry>
          <mesh>
            <scale>1 1 1</scale>
            <uri>model://matrice_600/meshes/Motor2_front_right_link.STL</uri>
          </mesh>
        </geometry>
      </collision>
      <visual name='Motor5_visual'>
        <pose>0 0 0 0 -0 0</pose>
        <geometry>
          <mesh>
            <scale>1 1 1</scale>
            <uri>model://matrice_600/meshes/Motor2_front_right_link.STL</uri>
          </mesh>
        </geometry>
      </visual>
    </link>
    <joint name='Motor2_joint' type='revolute'>
      <pose relative_to='base_link'>0.000409 0.57269 0.044614 0.13963 -0 0</pose>
      <parent>base_link</parent>
      <child>Motor2_link</child>
      <axis>
        <xyz>0 0 1</xyz>
        <limit>
          <lower>-1e+16</lower>
          <upper>1e+16</upper>
        </limit>
        <dynamics>
          <spring_reference>0</spring_reference>
          <spring_stiffness>0</spring_stiffness>
        </dynamics>
      </axis>
    </joint>
    <link name='Motor2_link'>
      <pose relative_to='Motor2_joint'>0 0 0 0 -0 0</pose>
      <inertial>
        <pose>-6e-06 -4e-06 0.038325 0 -0 0</pose>
        <mass>0.056995</mass>
        <inertia>
          <ixx>9.0324e-05</ixx>
          <ixy>-0.00012699</ixy>
          <ixz>2.4373e-11</ixz>
          <iyy>0.0001927</iyy>
          <iyz>1.3739e-10</iyz>
          <izz>0.00028179</izz>
        </inertia>
      </inertial>
      <collision name='Motor2_collision'>
        <pose>0 0 0 0 -0 0</pose>
        <geometry>
          <mesh>
            <scale>1 1 1</scale>
            <uri>model://matrice_600/meshes/Motor3_mid_left_link.STL</uri>
          </mesh>
        </geometry>
      </collision>
      <visual name='Motor2_visual'>
        <pose>0 0 0 0 -0 0</pose>
        <geometry>
          <mesh>
            <scale>1 1 1</scale>
            <uri>model://matrice_600/meshes/Motor3_mid_left_link.STL</uri>
          </mesh>
        </geometry>
      </visual>
    </link>
    <joint name='Motor1_joint' type='revolute'>
      <pose relative_to='base_link'>0.000409 -0.57451 0.032423 3.002 -0 0</pose>
      <parent>base_link</parent>
      <child>Motor1_link</child>
      <axis>
        <xyz>0 0 1</xyz>
        <limit>
          <lower>-1e+16</lower>
          <upper>1e+16</upper>
        </limit>
        <dynamics>
          <spring_reference>0</spring_reference>
          <spring_stiffness>0</spring_stiffness>
        </dynamics>
      </axis>
    </joint>
    <link name='Motor1_link'>
      <pose relative_to='Motor1_joint'>0 0 0 0 -0 0</pose>
      <inertial>
        <pose>-0.00558 -0.007688 -0.050635 0 -0 0</pose>
        <mass>0.11399</mass>
        <inertia>
          <ixx>0.00019862</ixx>
          <ixy>0.00025976</ixy>
          <ixz>-2.4438e-10</ixz>
          <iyy>0.00036742</iyy>
          <iyz>6.3124e-11</iyz>
          <izz>0.00056358</izz>
        </inertia>
      </inertial>
      <collision name='Motor1_collision'>
        <pose>0 0 0 0 -0 0</pose>
        <geometry>
          <mesh>
            <scale>1 1 1</scale>
            <uri>model://matrice_600/meshes/Motor4_mid_right_link.STL</uri>
          </mesh>
        </geometry>
      </collision>
      <visual name='Motor1_visual'>
        <pose>0 0 0 0 -0 0</pose>
        <geometry>
          <mesh>
            <scale>1 1 1</scale>
            <uri>model://matrice_600/meshes/Motor4_mid_right_link.STL</uri>
          </mesh>
        </geometry>
      </visual>
    </link>
    <joint name='Motor6_joint' type='revolute'>
      <pose relative_to='base_link'>-0.49641 0.28679 0.037986 3.002 -0 -2.0944</pose>
      <parent>base_link</parent>
      <child>Motor6_link</child>
      <axis>
        <xyz>0 0 1</xyz>
        <limit>
          <lower>-1e+16</lower>
          <upper>1e+16</upper>
        </limit>
        <dynamics>
          <spring_reference>0</spring_reference>
          <spring_stiffness>0</spring_stiffness>
        </dynamics>
      </axis>
    </joint>
    <link name='Motor6_link'>
      <pose relative_to='Motor6_joint'>0 0 0 0 -0 0</pose>
      <inertial>
        <pose>-0.003924 0.008651 -0.045018 0 -0 0</pose>
        <mass>0.11399</mass>
        <inertia>
          <ixx>0.00010297</ixx>
          <ixy>-0.00020537</ixy>
          <ixz>4.1347e-11</ixz>
          <iyy>0.00046308</iyy>
          <iyz>-6.8031e-10</iyz>
          <izz>0.00056358</izz>
        </inertia>
      </inertial>
      <collision name='Motor6_collision'>
        <pose>0 0 0 0 -0 0</pose>
        <geometry>
          <mesh>
            <scale>1 1 1</scale>
            <uri>model://matrice_600/meshes/Motor5_rear_left_link.STL</uri>
          </mesh>
        </geometry>
      </collision>
      <visual name='Motor6_visual'>
        <pose>0 0 0 0 -0 0</pose>
        <geometry>
          <mesh>
            <scale>1 1 1</scale>
            <uri>model://matrice_600/meshes/Motor5_rear_left_link.STL</uri>
          </mesh>
        </geometry>
      </visual>
    </link>
    <joint name='Motor4_joint' type='revolute'>
      <pose relative_to='base_link'>-0.49565 -0.28645 0.04424 0.070669 -0.12052 3.1331</pose>
      <parent>base_link</parent>
      <child>Motor4_link</child>
      <axis>
        <xyz>0 0 1</xyz>
        <limit>
          <lower>-1e+16</lower>
          <upper>1e+16</upper>
        </limit>
        <dynamics>
          <spring_reference>0</spring_reference>
          <spring_stiffness>0</spring_stiffness>
        </dynamics>
      </axis>
    </joint>
    <link name='Motor4_link'>
      <pose relative_to='Motor4_joint'>0 0 0 0 -0 0</pose>
      <inertial>
        <pose>-3e-06 -2e-06 0.038702 0 -0 0</pose>
        <mass>0.056994</mass>
        <inertia>
          <ixx>8.9059e-05</ixx>
          <ixy>-0.00012648</ixy>
          <ixz>-3.4413e-11</ixz>
          <iyy>0.00019396</iyy>
          <iyz>6.1704e-11</iyz>
          <izz>0.00028179</izz>
        </inertia>
      </inertial>
      <collision name='Motor4_collision'>
        <pose>0 0 0 0 -0 0</pose>
        <geometry>
          <mesh>
            <scale>1 1 1</scale>
            <uri>model://matrice_600/meshes/Motor6_rear_right_link.STL</uri>
          </mesh>
        </geometry>
      </collision>
      <visual name='Motor4_visual'>
        <pose>0 0 0 0 -0 0</pose>
        <geometry>
          <mesh>
            <scale>1 1 1</scale>
            <uri>model://matrice_600/meshes/Motor6_rear_right_link.STL</uri>
          </mesh>
        </geometry>
      </visual>
    </link>

    <plugin name='rosbag' filename='libgazebo_multirotor_base_plugin.so'>
      <robotNamespace/>
      <linkName>base_link</linkName>
      <rotorVelocitySlowdownSim>10</rotorVelocitySlowdownSim>
    </plugin>

    <plugin name='groundtruth_plugin' filename='libgazebo_groundtruth_plugin.so'>
      <robotNamespace/>
    </plugin>

    <include>
      <uri>model://gps</uri>
      <pose>0.05 0 0.04 0 0 0</pose>
      <name>gps0</name>
    </include>
    <joint name='gps0_joint' type='fixed'>
      <child>gps0::link</child>
      <parent>base_link</parent>
    </joint>
    <plugin name='motor_1' filename='libgazebo_motor_model.so'>
      <robotNamespace/>
      <jointName>Motor1_joint</jointName>
      <linkName>Motor1_link</linkName>
      <turningDirection>cw</turningDirection>
      <timeConstantUp>0.0125</timeConstantUp>
      <timeConstantDown>0.025</timeConstantDown>
      <maxRotVelocity>1100</maxRotVelocity>
      <motorConstant>5.84e-06</motorConstant>
      <momentConstant>0.06</momentConstant>
      <commandSubTopic>/gazebo/command/motor_speed</commandSubTopic>
      <motorNumber>0</motorNumber>
      <rotorDragCoefficient>0.000175</rotorDragCoefficient>
      <rollingMomentCoefficient>1e-06</rollingMomentCoefficient>
      <motorSpeedPubTopic>/motor_speed/0</motorSpeedPubTopic>
      <rotorVelocitySlowdownSim>10</rotorVelocitySlowdownSim>
    </plugin>
    <plugin name='motor_2' filename='libgazebo_motor_model.so'>
      <robotNamespace/>
      <jointName>Motor2_joint</jointName>
      <linkName>Motor2_link</linkName>
      <turningDirection>ccw</turningDirection>
      <timeConstantUp>0.0125</timeConstantUp>
      <timeConstantDown>0.025</timeConstantDown>
      <maxRotVelocity>1100</maxRotVelocity>
      <motorConstant>5.84e-06</motorConstant>
      <momentConstant>0.06</momentConstant>
      <commandSubTopic>/gazebo/command/motor_speed</commandSubTopic>
      <motorNumber>0</motorNumber>
      <rotorDragCoefficient>0.000175</rotorDragCoefficient>
      <rollingMomentCoefficient>1e-06</rollingMomentCoefficient>
      <motorSpeedPubTopic>/motor_speed/0</motorSpeedPubTopic>
      <rotorVelocitySlowdownSim>10</rotorVelocitySlowdownSim>
    </plugin>
    <plugin name='motor_3' filename='libgazebo_motor_model.so'>
      <robotNamespace/>
      <jointName>Motor3_joint</jointName>
      <linkName>Motor3_link</linkName>
      <turningDirection>cw</turningDirection>
      <timeConstantUp>0.0125</timeConstantUp>
      <timeConstantDown>0.025</timeConstantDown>
      <maxRotVelocity>1100</maxRotVelocity>
      <motorConstant>5.84e-06</motorConstant>
      <momentConstant>0.06</momentConstant>
      <commandSubTopic>/gazebo/command/motor_speed</commandSubTopic>
      <motorNumber>0</motorNumber>
      <rotorDragCoefficient>0.000175</rotorDragCoefficient>
      <rollingMomentCoefficient>1e-06</rollingMomentCoefficient>
      <motorSpeedPubTopic>/motor_speed/0</motorSpeedPubTopic>
      <rotorVelocitySlowdownSim>10</rotorVelocitySlowdownSim>
    </plugin>
    <plugin name='motor_4' filename='libgazebo_motor_model.so'>
      <robotNamespace/>
      <jointName>Motor4_joint</jointName>
      <linkName>Motor4_link</linkName>
      <turningDirection>ccw</turningDirection>
      <timeConstantUp>0.0125</timeConstantUp>
      <timeConstantDown>0.025</timeConstantDown>
      <maxRotVelocity>1100</maxRotVelocity>
      <motorConstant>5.84e-06</motorConstant>
      <momentConstant>0.06</momentConstant>
      <commandSubTopic>/gazebo/command/motor_speed</commandSubTopic>
      <motorNumber>0</motorNumber>
      <rotorDragCoefficient>0.000175</rotorDragCoefficient>
      <rollingMomentCoefficient>1e-06</rollingMomentCoefficient>
      <motorSpeedPubTopic>/motor_speed/0</motorSpeedPubTopic>
      <rotorVelocitySlowdownSim>10</rotorVelocitySlowdownSim>
    </plugin>
    <plugin name='motor_5' filename='libgazebo_motor_model.so'>
      <robotNamespace/>
      <jointName>Motor5_joint</jointName>
      <linkName>Motor5_link</linkName>
      <turningDirection>ccw</turningDirection>
      <timeConstantUp>0.0125</timeConstantUp>
      <timeConstantDown>0.025</timeConstantDown>
      <maxRotVelocity>1100</maxRotVelocity>
      <motorConstant>5.84e-06</motorConstant>
      <momentConstant>0.06</momentConstant>
      <commandSubTopic>/gazebo/command/motor_speed</commandSubTopic>
      <motorNumber>0</motorNumber>
      <rotorDragCoefficient>0.000175</rotorDragCoefficient>
      <rollingMomentCoefficient>1e-06</rollingMomentCoefficient>
      <motorSpeedPubTopic>/motor_speed/0</motorSpeedPubTopic>
      <rotorVelocitySlowdownSim>10</rotorVelocitySlowdownSim>
    </plugin>
    <plugin name='motor_6' filename='libgazebo_motor_model.so'>
      <robotNamespace/>
      <jointName>Motor6_joint</jointName>
      <linkName>Motor6_link</linkName>
      <turningDirection>cw</turningDirection>
      <timeConstantUp>0.0125</timeConstantUp>
      <timeConstantDown>0.025</timeConstantDown>
      <maxRotVelocity>1100</maxRotVelocity>
      <motorConstant>5.84e-06</motorConstant>
      <momentConstant>0.06</momentConstant>
      <commandSubTopic>/gazebo/command/motor_speed</commandSubTopic>
      <motorNumber>0</motorNumber>
      <rotorDragCoefficient>0.000175</rotorDragCoefficient>
      <rollingMomentCoefficient>1e-06</rollingMomentCoefficient>
      <motorSpeedPubTopic>/motor_speed/0</motorSpeedPubTopic>
      <rotorVelocitySlowdownSim>10</rotorVelocitySlowdownSim>
    </plugin>
     <plugin name='mavlink_interface' filename='libgazebo_mavlink_interface.so'>
      <robotNamespace/>
      <imuSubTopic>/imu</imuSubTopic>
      <gpsSubTopic>/gps</gpsSubTopic>
      <magSubTopic>/mag</magSubTopic>
      <baroSubTopic>/baro</baroSubTopic>
      <mavlink_addr>INADDR_ANY</mavlink_addr>
      <mavlink_udp_port>14560</mavlink_udp_port>
      <mavlink_tcp_port>4560</mavlink_tcp_port>
      <serialEnabled>0</serialEnabled>
      <serialDevice>/dev/ttyACM0</serialDevice>
      <baudRate>921600</baudRate>
      <qgc_addr>INADDR_ANY</qgc_addr>
      <qgc_udp_port>14550</qgc_udp_port>
      <sdk_addr>INADDR_ANY</sdk_addr>
      <sdk_udp_port>14540</sdk_udp_port>
      <hil_mode>0</hil_mode>
      <hil_state_level>0</hil_state_level>
      <vehicle_is_tailsitter>0</vehicle_is_tailsitter>
      <send_vision_estimation>0</send_vision_estimation>
      <send_odometry>1</send_odometry>
      <enable_lockstep>1</enable_lockstep>
      <use_tcp>1</use_tcp>
      <motorSpeedCommandPubTopic>/gazebo/command/motor_speed</motorSpeedCommandPubTopic>
      <control_channels>
        <channel name='rotor1'>
          <input_index>0</input_index>
          <input_offset>0</input_offset>
          <input_scaling>1000</input_scaling>
          <zero_position_disarmed>0</zero_position_disarmed>
          <zero_position_armed>0</zero_position_armed>
          <joint_control_type>velocity</joint_control_type>
        </channel>
        <channel name='rotor2'>
          <input_index>1</input_index>
          <input_offset>0</input_offset>
          <input_scaling>1000</input_scaling>
          <zero_position_disarmed>0</zero_position_disarmed>
          <zero_position_armed>0</zero_position_armed>
          <joint_control_type>velocity</joint_control_type>
        </channel>
        <channel name='rotor3'>
          <input_index>2</input_index>
          <input_offset>0</input_offset>
          <input_scaling>1000</input_scaling>
          <zero_position_disarmed>0</zero_position_disarmed>
          <zero_position_armed>0</zero_position_armed>
          <joint_control_type>velocity</joint_control_type>
        </channel>
        <channel name='rotor4'>
          <input_index>3</input_index>
          <input_offset>0</input_offset>
          <input_scaling>1000</input_scaling>
          <zero_position_disarmed>0</zero_position_disarmed>
          <zero_position_armed>100</zero_position_armed>
          <joint_control_type>velocity</joint_control_type>
        </channel>
        <channel name='rotor5'>
          <input_index>4</input_index>
          <input_offset>0</input_offset>
          <input_scaling>1000</input_scaling>
          <zero_position_disarmed>0</zero_position_disarmed>
          <zero_position_armed>0</zero_position_armed>
          <joint_control_type>velocity</joint_control_type>
        </channel>
        <channel name='rotor6'>
          <input_index>5</input_index>
          <input_offset>0</input_offset>
          <input_scaling>1000</input_scaling>
          <zero_position_disarmed>0</zero_position_disarmed>
          <zero_position_armed>0</zero_position_armed>
          <joint_control_type>velocity</joint_control_type>
        </channel>
      </control_channels>
    </plugin>

    <plugin name='barometer_plugin' filename='libgazebo_barometer_plugin.so'>
      <robotNamespace/>
      <pubRate>50</pubRate>
      <baroTopic>/baro</baroTopic>
      <baroDriftPaPerSec>0</baroDriftPaPerSec>
    </plugin>

    <plugin name='magnetometer_plugin' filename='libgazebo_magnetometer_plugin.so'>
      <robotNamespace/>
      <pubRate>100</pubRate>
      <noiseDensity>0.0004</noiseDensity>
      <randomWalk>6.4e-06</randomWalk>
      <biasCorrelationTime>600</biasCorrelationTime>
      <magTopic>/mag</magTopic>
    </plugin>

    <plugin name='rotors_gazebo_imu_plugin' filename='libgazebo_imu_plugin.so'>
      <robotNamespace/>
      <linkName>/imu_link</linkName>
      <imuTopic>/imu</imuTopic>
      <gyroscopeNoiseDensity>0.00018665</gyroscopeNoiseDensity>
      <gyroscopeRandomWalk>3.8785e-05</gyroscopeRandomWalk>
      <gyroscopeBiasCorrelationTime>1000.0</gyroscopeBiasCorrelationTime>
      <gyroscopeTurnOnBiasSigma>0.0087</gyroscopeTurnOnBiasSigma>
      <accelerometerNoiseDensity>0.00186</accelerometerNoiseDensity>
      <accelerometerRandomWalk>0.006</accelerometerRandomWalk>
      <accelerometerBiasCorrelationTime>300.0</accelerometerBiasCorrelationTime>
      <accelerometerTurnOnBiasSigma>0.196</accelerometerTurnOnBiasSigma>
    </plugin>
    
  </model>
</sdf>