<?xml version='1.0'?>
<sdf version='1.7'>
  <model name='matrice_600_nolanding'>
    <pose>0 0 0.6 0 0 0</pose>
    <link name='base_link'>
      <inertial>
        <!--<pose>-0.001268
        0.003183 0.533364 0 -0 0</pose>-->
        <pose>0 0 0 0 0 0</pose>
        <mass>6</mass>
        <inertia>
          <ixx>0.01</ixx>
          <ixy>0</ixy>
          <ixz>0</ixz>
          <iyy>0.01</iyy>
          <iyz>0</iyz>
          <izz>0.01</izz>
          <!-- 
          <ixx>12.4987</ixx>
          <ixy>0</ixy>
          <ixz>0</ixz>
          <iyy>9.94137</iyy>
          <iyz>4.55281</iyz>
          <izz>17.1522</izz>
          -->
        </inertia>
      </inertial>
      <self_collide>0</self_collide>
      <velocity_decay />
      <gravity>1</gravity>
      <visual name='base_link_visual'>
        <pose>0 0 0 0 0 0</pose>
        <geometry>
          <mesh>
            <scale>1 1 1</scale>
            <uri>model://matrice_600_nolanding/meshes/base_link.STL</uri>
          </mesh>
        </geometry>
        <material>
          <script>
            <name>Gazebo/DarkGrey</name>
            <uri>file://media/materials/scripts/gazebo.material</uri>
          </script>
        </material>
      </visual>
      <collision name='collision_1'>
        <pose>0 0 -0.15 0 -0 0</pose>
        <geometry>
          <box>
            <size>1.06792 1.22192 0.758715</size>
          </box>
        </geometry>
        <surface>
          <contac>
            <ode>
              <min_depth>0.001</min_depth>
              <max_vel>0</max_vel>
            </ode>
          </contac>
          <friction>
            <ode />
          </friction>
        </surface>
      </collision>
    </link>

    <!-- Imu link-->

    <link name='/imu_link'>
      <pose>0 0 0.02 0 0 0</pose>
      <inertial>
        <pose>0 0 0 0 0 0</pose>
        <mass>0.015</mass>
        <inertia>
          <ixx>1e-05</ixx>
          <ixy>0</ixy>
          <ixz>0</ixz>
          <iyy>1e-05</iyy>
          <iyz>0</iyz>
          <izz>1e-05</izz>
        </inertia>
      </inertial>
    </link>
    <joint name='/imu_joint' type='revolute'>
      <child>/imu_link</child>
      <parent>base_link</parent>
      <axis>
        <xyz>1 0 0</xyz>
        <limit>
          <lower>0</lower>
          <upper>0</upper>
          <effort>0</effort>
          <velocity>0</velocity>
        </limit>
        <dynamics>
          <spring_reference>0</spring_reference>
          <spring_stiffness>0</spring_stiffness>
        </dynamics>
        <use_parent_model_frame>1</use_parent_model_frame>
      </axis>
    </joint>

    <!-- Gps joint-->

    <include>
      <uri>model://gps</uri>
      <pose>0.05 0 0.04 0 0 0</pose>
      <name>gps0</name>
    </include>
    <joint name='gps0_joint' type='fixed'>
      <child>gps0::link</child>
      <parent>base_link</parent>
    </joint>

    <link name='rotor1_link'>
      <pose>0 -0.56635 0.11921 0 -0 0</pose>
      <inertial>
        <pose>0 0 0 0 0 0</pose>
        <mass>0.0230909</mass>
        <inertia>
          <ixx>1.55154e-07</ixx>
          <ixy>0</ixy>
          <ixz>0</ixz>
          <iyy>0</iyy>
          <iyz>0</iyz>
          <izz>4.47913e-05</izz>
        </inertia>
      </inertial>
      <visual name='rotor1_link_visual'>
        <pose>0 0 0 0 0 0</pose>
        <geometry>
          <mesh>
            <scale>1 1 1</scale>
            <uri>model://matrice_600_nolanding/meshes/rotor1_link.STL</uri>
          </mesh>
        </geometry>
        <material>
          <script>
            <name>Gazebo/Blue</name>
            <uri>file://media/materials/scripts/gazebo.material</uri>
          </script>
        </material>
      </visual>
      <collision name='rotor1_link_collision'>
        <pose>0 0 0 0 0 0</pose>
        <geometry>
          <box>
            <size>0.336036 0.23333 0.033432</size>
          </box>
        </geometry>
        <surface>
          <contact>
            <ode />
          </contact>
          <friction>
            <ode />
          </friction>
        </surface>
      </collision>
    </link>
    <link name='rotor2_link'>
      <pose>0 0.56635 0.11521 0 -0 0</pose>
      <inertial>
        <pose>0 0 0 0 0 0</pose>
        <mass>0.0230912</mass>
        <inertia>
          <ixx>1.55154e-07</ixx>
          <ixy>0</ixy>
          <ixz>0</ixz>
          <iyy>0</iyy>
          <iyz>0</iyz>
          <izz>4.47913e-05</izz>
        </inertia>
      </inertial>
      <visual name='rotor2_link_visual'>
        <pose>0 0 0 0 0 0</pose>
        <geometry>
          <mesh>
            <scale>1 1 1</scale>
            <uri>model://matrice_600_nolanding/meshes/rotor2_link.STL</uri>
          </mesh>
        </geometry>
        <material>
          <script>
            <name>Gazebo/Blue</name>
            <uri>file://media/materials/scripts/gazebo.material</uri>
          </script>
        </material>
      </visual>
      <collision name='rotor2_link_collision'>
        <pose>0 0 0 0 0 0</pose>
        <geometry>
          <box>
            <size>0.336036 0.23333 0.033432</size>
          </box>
        </geometry>
        <surface>
          <contact>
            <ode />
          </contact>
          <friction>
            <ode />
          </friction>
        </surface>
      </collision>
    </link>
    <link name='rotor3_link'>
      <pose>0.49047 0.28317 0.11921 0 -0 0</pose>
      <inertial>
        <pose>0 0 0 0 0 0</pose>
        <mass>0.0230901</mass>
        <inertia>
          <ixx>1.55154e-07</ixx>
          <ixy>0</ixy>
          <ixz>0</ixz>
          <iyy>0</iyy>
          <iyz>0</iyz>
          <izz>4.47913e-05</izz>
        </inertia>
      </inertial>
      <visual name='rotor3_link_visual'>
        <pose>0 0 0 0 0 0</pose>
        <geometry>
          <mesh>
            <scale>1 1 1</scale>
            <uri>model://matrice_600_nolanding/meshes/rotor3_link.STL</uri>
          </mesh>
        </geometry>
        <material>
          <script>
            <name>Gazebo/Blue</name>
            <uri>file://media/materials/scripts/gazebo.material</uri>
          </script>
        </material>
      </visual>
      <collision name='rotor3_link_collision'>
        <pose>0 0 0 0 0 0</pose>
        <geometry>
          <box>
            <size>0.336036 0.23333 0.033432</size>
          </box>
        </geometry>
        <surface>
          <contact>
            <ode />
          </contact>
          <friction>
            <ode />
          </friction>
        </surface>
      </collision>
    </link>
    <link name='rotor4_link'>
      <pose>-0.49047 -0.28317 0.11621 0 -0 0</pose>
      <inertial>
        <pose>0 0 0 0 0 0</pose>
        <mass>0.0230901</mass>
        <inertia>
          <ixx>1.55154e-07</ixx>
          <ixy>0</ixy>
          <ixz>0</ixz>
          <iyy>0</iyy>
          <iyz>0</iyz>
          <izz>4.47913e-05</izz>
        </inertia>
      </inertial>
      <visual name='rotor4_link_visual'>
        <pose>0 0 0 0 0 0</pose>
        <geometry>
          <mesh>
            <scale>1 1 1</scale>
            <uri>model://matrice_600_nolanding/meshes/rotor4_link.STL</uri>
          </mesh>
        </geometry>
        <material>
          <script>
            <name>Gazebo/Blue</name>
            <uri>file://media/materials/scripts/gazebo.material</uri>
          </script>
        </material>
      </visual>
      <collision name='rotor4_link_collision'>
        <pose>0 0 0 0 0 0</pose>
        <geometry>
          <box>
            <size>0.336036 0.23333 0.033432</size>
          </box>
        </geometry>
        <surface>
          <contact>
            <ode />
          </contact>
          <friction>
            <ode />
          </friction>
        </surface>
      </collision>
    </link>
    <link name='rotor5_link'>
      <pose>0.49047 -0.28317 0.11821 0 -0 0</pose>
      <inertial>
        <pose>0 0 0 0 0 0</pose>
        <mass>0.023092</mass>
        <inertia>
          <ixx>1.55154e-07</ixx>
          <ixy>0</ixy>
          <ixz>0</ixz>
          <iyy>0</iyy>
          <iyz>0</iyz>
          <izz>4.47913e-05</izz>
        </inertia>
      </inertial>
      <visual name='rotor5_link_visual'>
        <pose>0 0 0 0 0 0</pose>
        <geometry>
          <mesh>
            <scale>1 1 1</scale>
            <uri>model://matrice_600_nolanding/meshes/rotor5_link.STL</uri>
          </mesh>
        </geometry>
        <material>
          <script>
            <name>Gazebo/Blue</name>
            <uri>file://media/materials/scripts/gazebo.material</uri>
          </script>
        </material>
      </visual>
      <collision name='rotor5_link_collision'>
        <pose>0 0 0 0 0 0</pose>
        <geometry>
          <box>
            <size>0.336036 0.23333 0.033432</size>
          </box>
        </geometry>
        <surface>
          <contact>
            <ode />
          </contact>
          <friction>
            <ode />
          </friction>
        </surface>
      </collision>
    </link>
    <link name='rotor6_link'>
      <pose>-0.49047 0.28317 0.11621 0 -0 0</pose>
      <inertial>
        <pose>0 0 0 0 0 0</pose>
        <mass>0.023091</mass>
        <inertia>
          <ixx>1.55154e-07</ixx>
          <ixy>0</ixy>
          <ixz>0</ixz>
          <iyy>0</iyy>
          <iyz>0</iyz>
          <izz>4.47913e-05</izz>
        </inertia>
      </inertial>
      <visual name='rotor6_link_visual'>
        <pose>0 0 0 0 0 0</pose>
        <geometry>
          <mesh>
            <scale>1 1 1</scale>
            <uri>model://matrice_600_nolanding/meshes/rotor6_link.STL</uri>
          </mesh>
        </geometry>
        <material>
          <script>
            <name>Gazebo/Blue</name>
            <uri>file://media/materials/scripts/gazebo.material</uri>
          </script>
        </material>
      </visual>
      <collision name='rotor6_link_collision'>
        <pose>0 0 0 0 0 0</pose>
        <geometry>
          <box>
            <size>0.336036 0.23333 0.033432</size>
          </box>
        </geometry>
        <surface>
          <contact>
            <ode />
          </contact>
          <friction>
            <ode />
          </friction>
        </surface>
      </collision>
    </link>
    <joint name='rotor1_joint' type='revolute'>
      <parent>base_link</parent>
      <child>rotor1_link</child>
      <pose>0 0 0 0 0 0</pose>
      <axis>
        <xyz>0 0.13917 0.99027</xyz>
        <limit>
          <lower>-1e+16</lower>
          <upper>1e+16</upper>
          <effort>0.001</effort>
        </limit>
        <dynamics>
          <damping>0.005</damping>
        </dynamics>
        <use_parent_model_frame>1</use_parent_model_frame>
      </axis>
      <physics>
        <ode>
          <implicit_spring_damper>1</implicit_spring_damper>
        </ode>
      </physics>
    </joint>
    <joint name='rotor2_joint' type='revolute'>
      <parent>base_link</parent>
      <child>rotor2_link</child>
      <pose>0 0 0 0 0 0</pose>
      <axis>
        <xyz>0 -0.13917 0.99027</xyz>
        <limit>
          <lower>-1e+16</lower>
          <upper>1e+16</upper>
          <effort>0.001</effort>
        </limit>
        <dynamics>
          <damping>0.005</damping>
        </dynamics>
        <use_parent_model_frame>1</use_parent_model_frame>
      </axis>
      <physics>
        <ode>
          <implicit_spring_damper>1</implicit_spring_damper>
        </ode>
      </physics>
    </joint>
    <joint name='rotor3_joint' type='revolute'>
      <parent>base_link</parent>
      <child>rotor3_link</child>
      <pose>0 0 0 0 0 0</pose>
      <axis>
        <xyz>-0.12053 -0.069587 0.99027</xyz>
        <limit>
          <lower>-1e+16</lower>
          <upper>1e+16</upper>
          <effort>0.001</effort>
        </limit>
        <dynamics>
          <damping>0.005</damping>
        </dynamics>
        <use_parent_model_frame>1</use_parent_model_frame>
      </axis>
      <physics>
        <ode>
          <implicit_spring_damper>1</implicit_spring_damper>
        </ode>
      </physics>
    </joint>
    <joint name='rotor4_joint' type='revolute'>
      <parent>base_link</parent>
      <child>rotor4_link</child>
      <pose>0 0 0 0 0 0</pose>
      <axis>
        <xyz>0.12053 0.069587 0.99027</xyz>
        <limit>
          <lower>-1e+16</lower>
          <upper>1e+16</upper>
          <effort>0.001</effort>
        </limit>
        <dynamics>
          <damping>0.005</damping>
        </dynamics>
        <use_parent_model_frame>1</use_parent_model_frame>
      </axis>
      <physics>
        <ode>
          <implicit_spring_damper>1</implicit_spring_damper>
        </ode>
      </physics>
    </joint>
    <joint name='rotor5_joint' type='revolute'>
      <parent>base_link</parent>
      <child>rotor5_link</child>
      <pose>0 0 0 0 0 0</pose>
      <axis>
        <xyz>-0.12053 0.069587 0.99027</xyz>
        <limit>
          <lower>-1e+16</lower>
          <upper>1e+16</upper>
          <effort>0.001</effort>
        </limit>
        <dynamics>
          <damping>0.005</damping>
        </dynamics>
        <use_parent_model_frame>1</use_parent_model_frame>
      </axis>
      <physics>
        <ode>
          <implicit_spring_damper>1</implicit_spring_damper>
        </ode>
      </physics>
    </joint>
    <joint name='rotor6_joint' type='revolute'>
      <parent>base_link</parent>
      <child>rotor6_link</child>
      <pose>0 0 0 0 0 0</pose>
      <axis>
        <xyz>0.12053 -0.069587 0.99027</xyz>
        <limit>
          <lower>-1e+16</lower>
          <upper>1e+16</upper>
          <effort>0.001</effort>
        </limit>
        <dynamics>
          <damping>0.005</damping>
        </dynamics>
        <use_parent_model_frame>1</use_parent_model_frame>
      </axis>
      <physics>
        <ode>
          <implicit_spring_damper>1</implicit_spring_damper>
        </ode>
      </physics>
    </joint>
    <static>0</static>
    <allow_auto_disable>1</allow_auto_disable>

    <!-- Plugin defintion -->

    <plugin name='rosbag' filename='libgazebo_multirotor_base_plugin.so'>
      <robotNamespace />
      <linkName>base_link</linkName>
      <rotorVelocitySlowdownSim>10</rotorVelocitySlowdownSim>
    </plugin>

    <!-- plugin rotors definition -->

    <plugin name='rotor1_motor_model' filename='libgazebo_motor_model.so'>
      <robotNamespace />
      <jointName>rotor1_joint</jointName>
      <linkName>rotor1_link</linkName>
      <turningDirection>cw</turningDirection>
      <timeConstantUp>0.0125</timeConstantUp>
      <timeConstantDown>0.025</timeConstantDown>
      <maxRotVelocity>521</maxRotVelocity>
      <motorConstant>0.0002888</motorConstant>
      <momentConstant>0.07077</momentConstant>
      <commandSubTopic>/gazebo/command/motor_speed</commandSubTopic>
      <motorNumber>0</motorNumber>
      <rotorDragCoefficient>0.000919012</rotorDragCoefficient>
      <rollingMomentCoefficient>1e-06</rollingMomentCoefficient>
      <motorSpeedPubTopic>/motor_speed/0</motorSpeedPubTopic>
      <rotorVelocitySlowdownSim>10</rotorVelocitySlowdownSim>
    </plugin>

    <plugin name='rotor2_motor_model' filename='libgazebo_motor_model.so'>
      <robotNamespace />
      <jointName>rotor2_joint</jointName>
      <linkName>rotor2_link</linkName>
      <turningDirection>ccw</turningDirection>
      <timeConstantUp>0.0125</timeConstantUp>
      <timeConstantDown>0.025</timeConstantDown>
      <maxRotVelocity>521</maxRotVelocity>
      <motorConstant>0.0002888</motorConstant>
      <momentConstant>0.07077</momentConstant>
      <commandSubTopic>/gazebo/command/motor_speed</commandSubTopic>
      <motorNumber>1</motorNumber>
      <rotorDragCoefficient>0.000919012</rotorDragCoefficient>
      <rollingMomentCoefficient>1e-06</rollingMomentCoefficient>
      <motorSpeedPubTopic>/motor_speed/1</motorSpeedPubTopic>
      <rotorVelocitySlowdownSim>10</rotorVelocitySlowdownSim>
    </plugin>

    <plugin name='rotor3_motor_model' filename='libgazebo_motor_model.so'>
      <robotNamespace />
      <jointName>rotor3_joint</jointName>
      <linkName>rotor3_link</linkName>
      <turningDirection>cw</turningDirection>
      <timeConstantUp>0.0125</timeConstantUp>
      <timeConstantDown>0.025</timeConstantDown>
      <maxRotVelocity>521</maxRotVelocity>
      <motorConstant>0.0002888</motorConstant>
      <momentConstant>0.07077</momentConstant>
      <commandSubTopic>/gazebo/command/motor_speed</commandSubTopic>
      <motorNumber>2</motorNumber>
      <rotorDragCoefficient>0.000919012</rotorDragCoefficient>
      <rollingMomentCoefficient>1e-06</rollingMomentCoefficient>
      <motorSpeedPubTopic>/motor_speed/2</motorSpeedPubTopic>
      <rotorVelocitySlowdownSim>10</rotorVelocitySlowdownSim>
    </plugin>

    <plugin name='rotor4_motor_model' filename='libgazebo_motor_model.so'>
      <robotNamespace />
      <jointName>rotor4_joint</jointName>
      <linkName>rotor4_link</linkName>
      <turningDirection>ccw</turningDirection>
      <timeConstantUp>0.0125</timeConstantUp>
      <timeConstantDown>0.025</timeConstantDown>
      <maxRotVelocity>521</maxRotVelocity>
      <motorConstant>0.0002888</motorConstant>
      <momentConstant>0.07077</momentConstant>
      <commandSubTopic>/gazebo/command/motor_speed</commandSubTopic>
      <motorNumber>3</motorNumber>
      <rotorDragCoefficient>0.000919012</rotorDragCoefficient>
      <rollingMomentCoefficient>1e-06</rollingMomentCoefficient>
      <motorSpeedPubTopic>/motor_speed/3</motorSpeedPubTopic>
      <rotorVelocitySlowdownSim>10</rotorVelocitySlowdownSim>
    </plugin>

    <plugin name='rotor5_motor_model' filename='libgazebo_motor_model.so'>
      <robotNamespace />
      <jointName>rotor5_joint</jointName>
      <linkName>rotor5_link</linkName>
      <turningDirection>ccw</turningDirection>
      <timeConstantUp>0.0125</timeConstantUp>
      <timeConstantDown>0.025</timeConstantDown>
      <maxRotVelocity>521</maxRotVelocity>
      <motorConstant>0.0002888</motorConstant>
      <momentConstant>0.07077</momentConstant>
      <commandSubTopic>/gazebo/command/motor_speed</commandSubTopic>
      <motorNumber>4</motorNumber>
      <rotorDragCoefficient>0.000919012</rotorDragCoefficient>
      <rollingMomentCoefficient>1e-06</rollingMomentCoefficient>
      <motorSpeedPubTopic>/motor_speed/4</motorSpeedPubTopic>
      <rotorVelocitySlowdownSim>10</rotorVelocitySlowdownSim>
    </plugin>


    <plugin name='rotor6_motor_model' filename='libgazebo_motor_model.so'>
      <robotNamespace />
      <jointName>rotor6_joint</jointName>
      <linkName>rotor6_link</linkName>
      <turningDirection>cw</turningDirection>
      <timeConstantUp>0.0125</timeConstantUp>
      <timeConstantDown>0.025</timeConstantDown>
      <maxRotVelocity>521</maxRotVelocity>
      <motorConstant>0.0002888</motorConstant>
      <momentConstant>0.07077</momentConstant>
      <commandSubTopic>/gazebo/command/motor_speed</commandSubTopic>
      <motorNumber>5</motorNumber>
      <rotorDragCoefficient>0.000919012</rotorDragCoefficient>
      <rollingMomentCoefficient>1e-06</rollingMomentCoefficient>
      <motorSpeedPubTopic>/motor_speed/5</motorSpeedPubTopic>
      <rotorVelocitySlowdownSim>10</rotorVelocitySlowdownSim>
    </plugin>


    <plugin name='groundtruth_plugin' filename='libgazebo_groundtruth_plugin.so'>
      <robotNamespace />
    </plugin>


    <plugin name='magnetometer_plugin' filename='libgazebo_magnetometer_plugin.so'>
      <robotNamespace />
      <pubRate>100</pubRate>
      <noiseDensity>0.0004</noiseDensity>
      <randomWalk>6.4e-06</randomWalk>
      <biasCorrelationTime>600</biasCorrelationTime>
      <magTopic>/mag</magTopic>
    </plugin>


    <plugin name='barometer_plugin' filename='libgazebo_barometer_plugin.so'>
      <robotNamespace />
      <pubRate>50</pubRate>
      <baroTopic>/baro</baroTopic>
      <baroDriftPaPerSec>0</baroDriftPaPerSec>
    </plugin>

    <plugin name='rotors_gazebo_imu_plugin' filename='libgazebo_imu_plugin.so'>
      <robotNamespace />
      <linkName>/imu_link</linkName>
      <imuTopic>/imu</imuTopic>
      <gyroscopeNoiseDensity>0.00018665</gyroscopeNoiseDensity>
      <gyroscopeRandomWalk>3.8785e-05</gyroscopeRandomWalk>
      <gyroscopeBiasCorrelationTime>1000.0</gyroscopeBiasCorrelationTime>
      <gyroscopeTurnOnBiasSigma>0.0087</gyroscopeTurnOnBiasSigma>
      <accelerometerNoiseDensity>0.00186</accelerometerNoiseDensity>
      <accelerometerRandomWalk>0.006</accelerometerRandomWalk>
      <accelerometerBiasCorrelationTime>300.0</accelerometerBiasCorrelationTime>
      <accelerometerTurnOnBiasSigma>0.196</accelerometerTurnOnBiasSigma>
    </plugin>

    <plugin name='mavlink_interface' filename='libgazebo_mavlink_interface.so'>
      <robotNamespace />
      <imuSubTopic>/imu</imuSubTopic>
      <magSubTopic>/mag</magSubTopic>
      <baroSubTopic>/baro</baroSubTopic>
      <mavlink_addr>INADDR_ANY</mavlink_addr>
      <mavlink_tcp_port>4560</mavlink_tcp_port>
      <mavlink_udp_port>14560</mavlink_udp_port>
      <serialEnabled>0</serialEnabled>
      <serialDevice>/dev/ttyACM0</serialDevice>
      <baudRate>921600</baudRate>
      <qgc_addr>INADDR_ANY</qgc_addr>
      <qgc_udp_port>14550</qgc_udp_port>
      <sdk_addr>INADDR_ANY</sdk_addr>
      <sdk_udp_port>14540</sdk_udp_port>
      <hil_mode>0</hil_mode>
      <hil_state_level>0</hil_state_level>
      <send_vision_estimation>0</send_vision_estimation>
      <send_odometry>1</send_odometry>
      <enable_lockstep>1</enable_lockstep>
      <use_tcp>1</use_tcp>
      <motorSpeedCommandPubTopic>/gazebo/command/motor_speed</motorSpeedCommandPubTopic>
      <control_channels>
        <channel name="rotor1">
          <input_index>0</input_index>
          <input_offset>0</input_offset>
          <input_scaling>500</input_scaling>
          <zero_position_disarmed>0</zero_position_disarmed>
          <zero_position_armed>100</zero_position_armed>
          <joint_control_type>velocity</joint_control_type>
        </channel>
        <channel name="rotor2">
          <input_index>1</input_index>
          <input_offset>0</input_offset>
          <input_scaling>500</input_scaling>
          <zero_position_disarmed>0</zero_position_disarmed>
          <zero_position_armed>100</zero_position_armed>
          <joint_control_type>velocity</joint_control_type>
        </channel>
        <channel name="rotor3">
          <input_index>2</input_index>
          <input_offset>0</input_offset>
          <input_scaling>500</input_scaling>
          <zero_position_disarmed>0</zero_position_disarmed>
          <zero_position_armed>100</zero_position_armed>
          <joint_control_type>velocity</joint_control_type>
        </channel>
        <channel name="rotor4">
          <input_index>3</input_index>
          <input_offset>0</input_offset>
          <input_scaling>500</input_scaling>
          <zero_position_disarmed>0</zero_position_disarmed>
          <zero_position_armed>100</zero_position_armed>
          <joint_control_type>velocity</joint_control_type>
        </channel>
        <channel name="rotor5">
          <input_index>4</input_index>
          <input_offset>0</input_offset>
          <input_scaling>500</input_scaling>
          <zero_position_disarmed>0</zero_position_disarmed>
          <zero_position_armed>100</zero_position_armed>
          <joint_control_type>velocity</joint_control_type>
        </channel>
        <channel name="rotor6">
          <input_index>5</input_index>
          <input_offset>0</input_offset>
          <input_scaling>500</input_scaling>
          <zero_position_disarmed>0</zero_position_disarmed>
          <zero_position_armed>100</zero_position_armed>
          <joint_control_type>velocity</joint_control_type>
        </channel>
      </control_channels>
    </plugin>

  </model>
</sdf>